{
 "cells": [
  {
   "cell_type": "code",
   "execution_count": 32,
   "metadata": {},
   "outputs": [
    {
     "name": "stdout",
     "output_type": "stream",
     "text": [
      "2.15.0\n"
     ]
    }
   ],
   "source": [
    "import tensorflow as tf\n",
    "print(tf.__version__)"
   ]
  },
  {
   "cell_type": "markdown",
   "metadata": {},
   "source": [
    "# Problem Statement"
   ]
  },
  {
   "cell_type": "markdown",
   "metadata": {},
   "source": [
    "# Data Preprocessing"
   ]
  },
  {
   "cell_type": "code",
   "execution_count": 33,
   "metadata": {},
   "outputs": [
    {
     "name": "stdout",
     "output_type": "stream",
     "text": [
      "Found 9999 files belonging to 10 classes.\n",
      "Found 2000 files belonging to 10 classes.\n"
     ]
    }
   ],
   "source": [
    "import tensorflow as tf\n",
    "from tensorflow import keras\n",
    "\n",
    "train = tf.keras.utils.image_dataset_from_directory('CNN Data/train', labels = 'inferred')\n",
    "val = tf.keras.utils.image_dataset_from_directory('CNN Data/val', labels = 'inferred')"
   ]
  },
  {
   "cell_type": "markdown",
   "metadata": {},
   "source": [
    "# Deep Learning Model: CNN"
   ]
  },
  {
   "cell_type": "code",
   "execution_count": 34,
   "metadata": {},
   "outputs": [],
   "source": [
    "types = ['Amphibia', 'Animalia', 'Arachnida', 'Aves', 'Fungi', 'Insecta', 'Mammalia', 'Mollusca', 'Plantae', 'Reptilia']"
   ]
  },
  {
   "cell_type": "code",
   "execution_count": 35,
   "metadata": {},
   "outputs": [],
   "source": [
    "model = tf.keras.models.Sequential([\n",
    "    tf.keras.layers.Rescaling(1./255),\n",
    "    tf.keras.layers.RandomFlip(\"horizontal_and_vertical\"),\n",
    "    tf.keras.layers.RandomRotation(0.2),\n",
    "\n",
    "    tf.keras.layers.Conv2D(16, 3, padding = 'same', activation = 'relu'),\n",
    "    tf.keras.layers.MaxPooling2D(),\n",
    "    tf.keras.layers.Conv2D(32, 3, padding = 'same', activation = 'relu'),\n",
    "    tf.keras.layers.MaxPooling2D(),\n",
    "    tf.keras.layers.Conv2D(64, 3, padding = 'same', activation = 'relu'),\n",
    "    tf.keras.layers.MaxPooling2D(),\n",
    "\n",
    "\n",
    "    tf.keras.layers.Dropout(0.5),\n",
    "    tf.keras.layers.Flatten(),\n",
    "    \n",
    "    #tf.keras.layers.Dense(512, activation=tf.nn.relu),\n",
    "    #tf.keras.layers.Dense(256, activation=tf.nn.relu),\n",
    "    tf.keras.layers.Dense(128, activation=tf.nn.relu),\n",
    "    tf.keras.layers.Dense(10)#, activation=tf.nn.softmax)\n",
    "])"
   ]
  },
  {
   "cell_type": "code",
   "execution_count": 36,
   "metadata": {},
   "outputs": [],
   "source": [
    "class myCallback(tf.keras.callbacks.Callback):\n",
    "  def on_epoch_end(self, epoch, logs={}):\n",
    "    if(logs.get('val_accuracy') > 0.75):\n",
    "      print(\"Cancelling training.\")\n",
    "      self.model.stop_training = True\n",
    "\n",
    "callbacks = myCallback()"
   ]
  },
  {
   "cell_type": "code",
   "execution_count": 37,
   "metadata": {},
   "outputs": [
    {
     "name": "stdout",
     "output_type": "stream",
     "text": [
      "WARNING:tensorflow:`input_shape` is undefined or non-square, or `rows` is not in [128, 160, 192, 224]. Weights for input shape (224, 224) will be loaded as the default.\n"
     ]
    }
   ],
   "source": [
    "model = tf.keras.applications.mobilenet.MobileNet(\n",
    "    input_shape=None,\n",
    "    alpha=1.0,\n",
    "    depth_multiplier=1,\n",
    "    dropout=0.2,\n",
    "    include_top=False,\n",
    "    weights='imagenet',\n",
    "    input_tensor=None,\n",
    "    pooling=None,\n",
    "    classes=10,\n",
    "    classifier_activation='softmax'\n",
    ")"
   ]
  },
  {
   "cell_type": "code",
   "execution_count": 38,
   "metadata": {},
   "outputs": [],
   "source": [
    "model.compile(optimizer=tf.optimizers.Adam(),\n",
    "              loss=tf.keras.losses.SparseCategoricalCrossentropy(),#from_logits=True),\n",
    "              metrics=['accuracy'])"
   ]
  },
  {
   "cell_type": "code",
   "execution_count": 39,
   "metadata": {},
   "outputs": [
    {
     "name": "stdout",
     "output_type": "stream",
     "text": [
      "Epoch 1/60\n"
     ]
    },
    {
     "ename": "InvalidArgumentError",
     "evalue": "Graph execution error:\n\nDetected at node Equal defined at (most recent call last):\n  File \"<frozen runpy>\", line 198, in _run_module_as_main\n\n  File \"<frozen runpy>\", line 88, in _run_code\n\n  File \"C:\\Users\\g0dph\\AppData\\Roaming\\Python\\Python311\\site-packages\\ipykernel_launcher.py\", line 18, in <module>\n\n  File \"C:\\Users\\g0dph\\AppData\\Roaming\\Python\\Python311\\site-packages\\traitlets\\config\\application.py\", line 1075, in launch_instance\n\n  File \"C:\\Users\\g0dph\\AppData\\Roaming\\Python\\Python311\\site-packages\\ipykernel\\kernelapp.py\", line 739, in start\n\n  File \"C:\\Users\\g0dph\\AppData\\Roaming\\Python\\Python311\\site-packages\\tornado\\platform\\asyncio.py\", line 205, in start\n\n  File \"c:\\Users\\g0dph\\AppData\\Local\\Programs\\Python\\Python311\\Lib\\asyncio\\base_events.py\", line 608, in run_forever\n\n  File \"c:\\Users\\g0dph\\AppData\\Local\\Programs\\Python\\Python311\\Lib\\asyncio\\base_events.py\", line 1936, in _run_once\n\n  File \"c:\\Users\\g0dph\\AppData\\Local\\Programs\\Python\\Python311\\Lib\\asyncio\\events.py\", line 84, in _run\n\n  File \"C:\\Users\\g0dph\\AppData\\Roaming\\Python\\Python311\\site-packages\\ipykernel\\kernelbase.py\", line 542, in dispatch_queue\n\n  File \"C:\\Users\\g0dph\\AppData\\Roaming\\Python\\Python311\\site-packages\\ipykernel\\kernelbase.py\", line 531, in process_one\n\n  File \"C:\\Users\\g0dph\\AppData\\Roaming\\Python\\Python311\\site-packages\\ipykernel\\kernelbase.py\", line 437, in dispatch_shell\n\n  File \"C:\\Users\\g0dph\\AppData\\Roaming\\Python\\Python311\\site-packages\\ipykernel\\ipkernel.py\", line 359, in execute_request\n\n  File \"C:\\Users\\g0dph\\AppData\\Roaming\\Python\\Python311\\site-packages\\ipykernel\\kernelbase.py\", line 775, in execute_request\n\n  File \"C:\\Users\\g0dph\\AppData\\Roaming\\Python\\Python311\\site-packages\\ipykernel\\ipkernel.py\", line 446, in do_execute\n\n  File \"C:\\Users\\g0dph\\AppData\\Roaming\\Python\\Python311\\site-packages\\ipykernel\\zmqshell.py\", line 549, in run_cell\n\n  File \"C:\\Users\\g0dph\\AppData\\Roaming\\Python\\Python311\\site-packages\\IPython\\core\\interactiveshell.py\", line 3051, in run_cell\n\n  File \"C:\\Users\\g0dph\\AppData\\Roaming\\Python\\Python311\\site-packages\\IPython\\core\\interactiveshell.py\", line 3106, in _run_cell\n\n  File \"C:\\Users\\g0dph\\AppData\\Roaming\\Python\\Python311\\site-packages\\IPython\\core\\async_helpers.py\", line 129, in _pseudo_sync_runner\n\n  File \"C:\\Users\\g0dph\\AppData\\Roaming\\Python\\Python311\\site-packages\\IPython\\core\\interactiveshell.py\", line 3311, in run_cell_async\n\n  File \"C:\\Users\\g0dph\\AppData\\Roaming\\Python\\Python311\\site-packages\\IPython\\core\\interactiveshell.py\", line 3493, in run_ast_nodes\n\n  File \"C:\\Users\\g0dph\\AppData\\Roaming\\Python\\Python311\\site-packages\\IPython\\core\\interactiveshell.py\", line 3553, in run_code\n\n  File \"C:\\Users\\g0dph\\AppData\\Local\\Temp\\ipykernel_29212\\3513618728.py\", line 1, in <module>\n\n  File \"c:\\Users\\g0dph\\AppData\\Local\\Programs\\Python\\Python311\\Lib\\site-packages\\keras\\src\\utils\\traceback_utils.py\", line 65, in error_handler\n\n  File \"c:\\Users\\g0dph\\AppData\\Local\\Programs\\Python\\Python311\\Lib\\site-packages\\keras\\src\\engine\\training.py\", line 1807, in fit\n\n  File \"c:\\Users\\g0dph\\AppData\\Local\\Programs\\Python\\Python311\\Lib\\site-packages\\keras\\src\\engine\\training.py\", line 1401, in train_function\n\n  File \"c:\\Users\\g0dph\\AppData\\Local\\Programs\\Python\\Python311\\Lib\\site-packages\\keras\\src\\engine\\training.py\", line 1384, in step_function\n\n  File \"c:\\Users\\g0dph\\AppData\\Local\\Programs\\Python\\Python311\\Lib\\site-packages\\keras\\src\\engine\\training.py\", line 1373, in run_step\n\n  File \"c:\\Users\\g0dph\\AppData\\Local\\Programs\\Python\\Python311\\Lib\\site-packages\\keras\\src\\engine\\training.py\", line 1155, in train_step\n\n  File \"c:\\Users\\g0dph\\AppData\\Local\\Programs\\Python\\Python311\\Lib\\site-packages\\keras\\src\\engine\\training.py\", line 1249, in compute_metrics\n\n  File \"c:\\Users\\g0dph\\AppData\\Local\\Programs\\Python\\Python311\\Lib\\site-packages\\keras\\src\\engine\\compile_utils.py\", line 620, in update_state\n\n  File \"c:\\Users\\g0dph\\AppData\\Local\\Programs\\Python\\Python311\\Lib\\site-packages\\keras\\src\\utils\\metrics_utils.py\", line 77, in decorated\n\n  File \"c:\\Users\\g0dph\\AppData\\Local\\Programs\\Python\\Python311\\Lib\\site-packages\\keras\\src\\metrics\\base_metric.py\", line 140, in update_state_fn\n\n  File \"c:\\Users\\g0dph\\AppData\\Local\\Programs\\Python\\Python311\\Lib\\site-packages\\keras\\src\\metrics\\base_metric.py\", line 723, in update_state\n\n  File \"c:\\Users\\g0dph\\AppData\\Local\\Programs\\Python\\Python311\\Lib\\site-packages\\keras\\src\\metrics\\accuracy_metrics.py\", line 459, in sparse_categorical_accuracy\n\n  File \"c:\\Users\\g0dph\\AppData\\Local\\Programs\\Python\\Python311\\Lib\\site-packages\\keras\\src\\utils\\metrics_utils.py\", line 969, in sparse_categorical_matches\n\nIncompatible shapes: [32] vs. [32,8,8]\n\t [[{{node Equal}}]] [Op:__inference_train_function_45293]",
     "output_type": "error",
     "traceback": [
      "\u001b[1;31m---------------------------------------------------------------------------\u001b[0m",
      "\u001b[1;31mInvalidArgumentError\u001b[0m                      Traceback (most recent call last)",
      "Cell \u001b[1;32mIn[39], line 1\u001b[0m\n\u001b[1;32m----> 1\u001b[0m \u001b[43mmodel\u001b[49m\u001b[38;5;241;43m.\u001b[39;49m\u001b[43mfit\u001b[49m\u001b[43m(\u001b[49m\u001b[43mtrain\u001b[49m\u001b[43m,\u001b[49m\u001b[43m \u001b[49m\u001b[43mvalidation_data\u001b[49m\u001b[38;5;241;43m=\u001b[39;49m\u001b[43mval\u001b[49m\u001b[43m,\u001b[49m\u001b[43m \u001b[49m\u001b[43mepochs\u001b[49m\u001b[38;5;241;43m=\u001b[39;49m\u001b[38;5;241;43m60\u001b[39;49m\u001b[43m)\u001b[49m\u001b[38;5;66;03m#, callbacks=[callbacks])\u001b[39;00m\n",
      "File \u001b[1;32mc:\\Users\\g0dph\\AppData\\Local\\Programs\\Python\\Python311\\Lib\\site-packages\\keras\\src\\utils\\traceback_utils.py:70\u001b[0m, in \u001b[0;36mfilter_traceback.<locals>.error_handler\u001b[1;34m(*args, **kwargs)\u001b[0m\n\u001b[0;32m     67\u001b[0m     filtered_tb \u001b[38;5;241m=\u001b[39m _process_traceback_frames(e\u001b[38;5;241m.\u001b[39m__traceback__)\n\u001b[0;32m     68\u001b[0m     \u001b[38;5;66;03m# To get the full stack trace, call:\u001b[39;00m\n\u001b[0;32m     69\u001b[0m     \u001b[38;5;66;03m# `tf.debugging.disable_traceback_filtering()`\u001b[39;00m\n\u001b[1;32m---> 70\u001b[0m     \u001b[38;5;28;01mraise\u001b[39;00m e\u001b[38;5;241m.\u001b[39mwith_traceback(filtered_tb) \u001b[38;5;28;01mfrom\u001b[39;00m \u001b[38;5;28;01mNone\u001b[39;00m\n\u001b[0;32m     71\u001b[0m \u001b[38;5;28;01mfinally\u001b[39;00m:\n\u001b[0;32m     72\u001b[0m     \u001b[38;5;28;01mdel\u001b[39;00m filtered_tb\n",
      "File \u001b[1;32mc:\\Users\\g0dph\\AppData\\Local\\Programs\\Python\\Python311\\Lib\\site-packages\\tensorflow\\python\\eager\\execute.py:53\u001b[0m, in \u001b[0;36mquick_execute\u001b[1;34m(op_name, num_outputs, inputs, attrs, ctx, name)\u001b[0m\n\u001b[0;32m     51\u001b[0m \u001b[38;5;28;01mtry\u001b[39;00m:\n\u001b[0;32m     52\u001b[0m   ctx\u001b[38;5;241m.\u001b[39mensure_initialized()\n\u001b[1;32m---> 53\u001b[0m   tensors \u001b[38;5;241m=\u001b[39m pywrap_tfe\u001b[38;5;241m.\u001b[39mTFE_Py_Execute(ctx\u001b[38;5;241m.\u001b[39m_handle, device_name, op_name,\n\u001b[0;32m     54\u001b[0m                                       inputs, attrs, num_outputs)\n\u001b[0;32m     55\u001b[0m \u001b[38;5;28;01mexcept\u001b[39;00m core\u001b[38;5;241m.\u001b[39m_NotOkStatusException \u001b[38;5;28;01mas\u001b[39;00m e:\n\u001b[0;32m     56\u001b[0m   \u001b[38;5;28;01mif\u001b[39;00m name \u001b[38;5;129;01mis\u001b[39;00m \u001b[38;5;129;01mnot\u001b[39;00m \u001b[38;5;28;01mNone\u001b[39;00m:\n",
      "\u001b[1;31mInvalidArgumentError\u001b[0m: Graph execution error:\n\nDetected at node Equal defined at (most recent call last):\n  File \"<frozen runpy>\", line 198, in _run_module_as_main\n\n  File \"<frozen runpy>\", line 88, in _run_code\n\n  File \"C:\\Users\\g0dph\\AppData\\Roaming\\Python\\Python311\\site-packages\\ipykernel_launcher.py\", line 18, in <module>\n\n  File \"C:\\Users\\g0dph\\AppData\\Roaming\\Python\\Python311\\site-packages\\traitlets\\config\\application.py\", line 1075, in launch_instance\n\n  File \"C:\\Users\\g0dph\\AppData\\Roaming\\Python\\Python311\\site-packages\\ipykernel\\kernelapp.py\", line 739, in start\n\n  File \"C:\\Users\\g0dph\\AppData\\Roaming\\Python\\Python311\\site-packages\\tornado\\platform\\asyncio.py\", line 205, in start\n\n  File \"c:\\Users\\g0dph\\AppData\\Local\\Programs\\Python\\Python311\\Lib\\asyncio\\base_events.py\", line 608, in run_forever\n\n  File \"c:\\Users\\g0dph\\AppData\\Local\\Programs\\Python\\Python311\\Lib\\asyncio\\base_events.py\", line 1936, in _run_once\n\n  File \"c:\\Users\\g0dph\\AppData\\Local\\Programs\\Python\\Python311\\Lib\\asyncio\\events.py\", line 84, in _run\n\n  File \"C:\\Users\\g0dph\\AppData\\Roaming\\Python\\Python311\\site-packages\\ipykernel\\kernelbase.py\", line 542, in dispatch_queue\n\n  File \"C:\\Users\\g0dph\\AppData\\Roaming\\Python\\Python311\\site-packages\\ipykernel\\kernelbase.py\", line 531, in process_one\n\n  File \"C:\\Users\\g0dph\\AppData\\Roaming\\Python\\Python311\\site-packages\\ipykernel\\kernelbase.py\", line 437, in dispatch_shell\n\n  File \"C:\\Users\\g0dph\\AppData\\Roaming\\Python\\Python311\\site-packages\\ipykernel\\ipkernel.py\", line 359, in execute_request\n\n  File \"C:\\Users\\g0dph\\AppData\\Roaming\\Python\\Python311\\site-packages\\ipykernel\\kernelbase.py\", line 775, in execute_request\n\n  File \"C:\\Users\\g0dph\\AppData\\Roaming\\Python\\Python311\\site-packages\\ipykernel\\ipkernel.py\", line 446, in do_execute\n\n  File \"C:\\Users\\g0dph\\AppData\\Roaming\\Python\\Python311\\site-packages\\ipykernel\\zmqshell.py\", line 549, in run_cell\n\n  File \"C:\\Users\\g0dph\\AppData\\Roaming\\Python\\Python311\\site-packages\\IPython\\core\\interactiveshell.py\", line 3051, in run_cell\n\n  File \"C:\\Users\\g0dph\\AppData\\Roaming\\Python\\Python311\\site-packages\\IPython\\core\\interactiveshell.py\", line 3106, in _run_cell\n\n  File \"C:\\Users\\g0dph\\AppData\\Roaming\\Python\\Python311\\site-packages\\IPython\\core\\async_helpers.py\", line 129, in _pseudo_sync_runner\n\n  File \"C:\\Users\\g0dph\\AppData\\Roaming\\Python\\Python311\\site-packages\\IPython\\core\\interactiveshell.py\", line 3311, in run_cell_async\n\n  File \"C:\\Users\\g0dph\\AppData\\Roaming\\Python\\Python311\\site-packages\\IPython\\core\\interactiveshell.py\", line 3493, in run_ast_nodes\n\n  File \"C:\\Users\\g0dph\\AppData\\Roaming\\Python\\Python311\\site-packages\\IPython\\core\\interactiveshell.py\", line 3553, in run_code\n\n  File \"C:\\Users\\g0dph\\AppData\\Local\\Temp\\ipykernel_29212\\3513618728.py\", line 1, in <module>\n\n  File \"c:\\Users\\g0dph\\AppData\\Local\\Programs\\Python\\Python311\\Lib\\site-packages\\keras\\src\\utils\\traceback_utils.py\", line 65, in error_handler\n\n  File \"c:\\Users\\g0dph\\AppData\\Local\\Programs\\Python\\Python311\\Lib\\site-packages\\keras\\src\\engine\\training.py\", line 1807, in fit\n\n  File \"c:\\Users\\g0dph\\AppData\\Local\\Programs\\Python\\Python311\\Lib\\site-packages\\keras\\src\\engine\\training.py\", line 1401, in train_function\n\n  File \"c:\\Users\\g0dph\\AppData\\Local\\Programs\\Python\\Python311\\Lib\\site-packages\\keras\\src\\engine\\training.py\", line 1384, in step_function\n\n  File \"c:\\Users\\g0dph\\AppData\\Local\\Programs\\Python\\Python311\\Lib\\site-packages\\keras\\src\\engine\\training.py\", line 1373, in run_step\n\n  File \"c:\\Users\\g0dph\\AppData\\Local\\Programs\\Python\\Python311\\Lib\\site-packages\\keras\\src\\engine\\training.py\", line 1155, in train_step\n\n  File \"c:\\Users\\g0dph\\AppData\\Local\\Programs\\Python\\Python311\\Lib\\site-packages\\keras\\src\\engine\\training.py\", line 1249, in compute_metrics\n\n  File \"c:\\Users\\g0dph\\AppData\\Local\\Programs\\Python\\Python311\\Lib\\site-packages\\keras\\src\\engine\\compile_utils.py\", line 620, in update_state\n\n  File \"c:\\Users\\g0dph\\AppData\\Local\\Programs\\Python\\Python311\\Lib\\site-packages\\keras\\src\\utils\\metrics_utils.py\", line 77, in decorated\n\n  File \"c:\\Users\\g0dph\\AppData\\Local\\Programs\\Python\\Python311\\Lib\\site-packages\\keras\\src\\metrics\\base_metric.py\", line 140, in update_state_fn\n\n  File \"c:\\Users\\g0dph\\AppData\\Local\\Programs\\Python\\Python311\\Lib\\site-packages\\keras\\src\\metrics\\base_metric.py\", line 723, in update_state\n\n  File \"c:\\Users\\g0dph\\AppData\\Local\\Programs\\Python\\Python311\\Lib\\site-packages\\keras\\src\\metrics\\accuracy_metrics.py\", line 459, in sparse_categorical_accuracy\n\n  File \"c:\\Users\\g0dph\\AppData\\Local\\Programs\\Python\\Python311\\Lib\\site-packages\\keras\\src\\utils\\metrics_utils.py\", line 969, in sparse_categorical_matches\n\nIncompatible shapes: [32] vs. [32,8,8]\n\t [[{{node Equal}}]] [Op:__inference_train_function_45293]"
     ]
    }
   ],
   "source": [
    "model.fit(train, validation_data=val, epochs=60)#, callbacks=[callbacks])"
   ]
  },
  {
   "cell_type": "markdown",
   "metadata": {},
   "source": [
    "# Evaluation of Model"
   ]
  },
  {
   "cell_type": "code",
   "execution_count": null,
   "metadata": {},
   "outputs": [
    {
     "name": "stdout",
     "output_type": "stream",
     "text": [
      "63/63 [==============================] - 2s 22ms/step - loss: 2.0659 - accuracy: 0.3910\n"
     ]
    },
    {
     "data": {
      "text/plain": [
       "[2.065906524658203, 0.39100000262260437]"
      ]
     },
     "execution_count": 162,
     "metadata": {},
     "output_type": "execute_result"
    }
   ],
   "source": [
    "model.evaluate(val)"
   ]
  },
  {
   "cell_type": "markdown",
   "metadata": {},
   "source": [
    "# Hyperparameter Tuning"
   ]
  }
 ],
 "metadata": {
  "kernelspec": {
   "display_name": "Python 3",
   "language": "python",
   "name": "python3"
  },
  "language_info": {
   "codemirror_mode": {
    "name": "ipython",
    "version": 3
   },
   "file_extension": ".py",
   "mimetype": "text/x-python",
   "name": "python",
   "nbconvert_exporter": "python",
   "pygments_lexer": "ipython3",
   "version": "3.11.8"
  }
 },
 "nbformat": 4,
 "nbformat_minor": 2
}
